Workbook

Sheet cards
A1: Set | B1: Nm | C1: Fac | D1: Fac Nm | E1: Name | F1: Type | G1: SubType | H1: Cst | I1: Atk | J1: Life | K1: Sh | L1: Abilities1 | M1: Abilities2
A3: C | B3: =IF(A3="","",IF(A2=A3,B2+1,1)) -> 1 | C3: Apoc | D3: =IF(C3="","",IF(C3=C2,D2+1,1)) -> 1 | E3: Set Overwatch | F3: Apoc | G3: Base | L3: Use before carrying out an order for a Detachment. The order is changed to Aimed Fire.
A4: C | B4: =IF(A4="","",IF(A3=A4,B3+1,1)) -> 2 | C4: Apoc | D4: =IF(C4="","",IF(C4=C3,D3+1,1)) -> 2 | E4: Signal Advance | F4: Apoc | G4: Base | L4: Use before carrying out an order for a Detachment. The order is changed to Advance.
A5: C | B5: =IF(A5="","",IF(A4=A5,B4+1,1)) -> 3 | C5: Apoc | D5: =IF(C5="","",IF(C5=C4,D4+1,1)) -> 3 | E5: Forward, For Glory | F5: Apoc | G5: Base | L5: Use before carrying out an order for a Detachment. The order is changed to Assault.
A6: C | B6: =IF(A6="","",IF(A5=A6,B5+1,1)) -> 4 | C6: Apoc | D6: =IF(C6="","",IF(C6=C5,D5+1,1)) -> 4 | E6: Look out, Sir! | F6: Apoc | G6: Base | L6: Use at the start of the Damage phase. A Light Character can remove D3 blast markers and put it on a friendly light unit with 6” of it.
A7: C | B7: =IF(A7="","",IF(A6=A7,B6+1,1)) -> 5 | C7: Apoc | D7: =IF(C7="","",IF(C7=C6,D6+1,1)) -> 5 | E7: Divine Intervention | F7: Apoc | G7: Base | L7: Use after rolling any dice in Orders, Action or Damage phase. Change the result of 1 dice to any of your choosing.
A8: C | B8: =IF(A8="","",IF(A7=A8,B7+1,1)) -> 6 | C8: Apoc | D8: =IF(C8="","",IF(C8=C7,D7+1,1)) -> 6 | E8: Strike True | F8: Apoc | G8: Base | L8: Reroll the dice for a single Wound roll.
A9: C | B9: =IF(A9="","",IF(A8=A9,B8+1,1)) -> 7 | C9: Apoc | D9: =IF(C9="","",IF(C9=C8,D8+1,1)) -> 7 | E9: Miraculous Escape | F9: Apoc | G9: Base | L9: Use in the Damage Phase. Remove 1 blast marker on a friendly unit.
A10: C | B10: =IF(A10="","",IF(A9=A10,B9+1,1)) -> 8 | C10: Apoc | D10: =IF(C10="","",IF(C10=C9,D9+1,1)) -> 8 | E10: Go to Ground | F10: Apoc | G10: Base | L10: Use at start of the Damage phase. 1 Infantry unit not in base contact with an enemy unit doubles their saving throw results until the end of the phase.
A11: C | B11: =IF(A11="","",IF(A10=A11,B10+1,1)) -> 9 | C11: Apoc | D11: =IF(C11="","",IF(C11=C10,D10+1,1)) -> 9 | E11: Medical Suppies | F11: Apoc | G11: Base | L11: Use at the start of the Action phase. Remove d3 damage markers from a light unit. | M11: remove
A12: C | B12: =IF(A12="","",IF(A11=A12,B11+1,1)) -> 10 | C12: Apoc | D12: =IF(C12="","",IF(C12=C11,D11+1,1)) -> 10 | E12: Aim True | F12: Apoc | G12: Base | L12: Reroll the dice for a single Hit Roll. | M12: remove
A13: C | B13: =IF(A13="","",IF(A12=A13,B12+1,1)) -> 11 | C13: Apoc | D13: =IF(C13="","",IF(C13=C12,D12+1,1)) -> 11 | E13: Finest Hour | F13: Apoc | G13: Extra | L13: Use in action phase. Select 1 warmaster or Warlord. Until the end of the turn, add 1 to the unit's Attacks characteristic, add 2 to wound rolls for that unit's melee attacks, and the units melee attacks gain Destroyer.
A14: C | B14: =IF(A14="","",IF(A13=A14,B13+1,1)) -> 12 | C14: Apoc | D14: =IF(C14="","",IF(C14=C13,D13+1,1)) -> 12 | E14: Armour of Contempt | F14: Apoc | G14: Extra | L14: Use in the Damage phase. 1 unit rolls D12s for all their saving throws, regardless of the blast type.
A15: C | B15: =IF(A15="","",IF(A14=A15,B14+1,1)) -> 13 | C15: Apoc | D15: =IF(C15="","",IF(C15=C14,D14+1,1)) -> 13 | E15: Deny the Witch | F15: Apoc | G15: Extra | L15: Use when an enemy uses a Psychic Command Asset before resolving it. Roll a D12. On a 4+, cancel that asset.
A16: C | B16: =IF(A16="","",IF(A15=A16,B15+1,1)) -> 14 | C16: Apoc | D16: =IF(C16="","",IF(C16=C15,D15+1,1)) -> 14 | E16: Capture & Control | F16: Apoc | G16: Extra | L16: Use at the end of a turn. When used, select 1 objective marker in your control. You count as controlling that objective marker (even without units near it), until an enemy takes control of the marker.
A17: C | B17: =IF(A17="","",IF(A16=A17,B16+1,1)) -> 15 | C17: Apoc | D17: =IF(C17="","",IF(C17=C16,D16+1,1)) -> 15 | E17: Noble Sacrifice | F17: Apoc | G17: Extra | L17: Use when a friendly unit is destroyed, if it could explode or crush those nearby, it automatically explodes or crushes those nearby. Otherwise, place a blast marker near the closest enemy unit within 3”.
A18: C | B18: =IF(A18="","",IF(A17=A18,B17+1,1)) -> 16 | C18: Apoc | D18: =IF(C18="","",IF(C18=C17,D17+1,1)) -> 16 | E18: Reinforcements | F18: Apoc | G18: Extra | L18: Use in the Reinforcements Step. Select 1 destroyed non-character unit and roll a d12. If it's over the unit's power level, return it to the battlefield within 6” of a battlefield edge and 9” from enemy units. It is a brand new detachment. Otherwise return this card to your hand and you can't use it this turn.
A19: C | B19: =IF(A19="","",IF(A18=A19,B18+1,1)) -> 17 | C19: Apoc | D19: =IF(C19="","",IF(C19=C18,D18+1,1)) -> 17 | E19: Insane Bravery | F19: Apoc | G19: Extra | L19: Use when a unit fails a moral test. That unit passes the test instead.
A20: C | B20: =IF(A20="","",IF(A19=A20,B19+1,1)) -> 18 | C20: Apoc | D20: =IF(C20="","",IF(C20=C19,D19+1,1)) -> 18 | E20: Hold at All Costs | F20: Apoc | G20: Extra | L20: Use in any phase. Select 1 friendly unit. Until end of battle, that unit has the 'Objective Secured' ability. This turn, if it is a character, that unit can roll a D12 instead of a D6 for one Armour Save roll.
A21: C | B21: =IF(A21="","",IF(A20=A21,B20+1,1)) -> 19 | C21: Apoc | D21: =IF(C21="","",IF(C21=C20,D20+1,1)) -> 19 | E21: Behind Enemy Lines | F21: Apoc | G21: Extra | L21: Use in any phase.A unit discards all 'out of command' tokens and never gains them for the rest of the battle.
A22: C | B22: =IF(A22="","",IF(A21=A22,B21+1,1)) -> 20 | C22: Apoc | D22: =IF(C22="","",IF(C22=C21,D21+1,1)) -> 20 | E22: Seize the Initiative | F22: Apoc | G22: Extra | L22: Use after a detachment has performed an order. You can choose a detachment to perform their order next, out of order.
A23: C | B23: =IF(A23="","",IF(A22=A23,B22+1,1)) -> 21 | C23: Apoc | D23: =IF(C23="","",IF(C23=C22,D22+1,1)) -> 21 | E23: Overwhelming Firepower | F23: Apoc | G23: Extra | L23: Use before carrying out an order for a Detachment that chose Aimed Fire. Until the end of the phase, re-roll hit rolls of 1 for attacks from units in that detachment.
A24: C | B24: =IF(A24="","",IF(A23=A24,B23+1,1)) -> 22 | C24: Apoc | D24: =IF(C24="","",IF(C24=C23,D23+1,1)) -> 22 | E24: Blood And Guts | F24: Apoc | G24: Extra | L24: Use before carrying out an order for a Detachment that chose Assault. Until the end of the phase, re-roll hit rolls of 1 for attacks from units in that detachment.
... A27: C | B27: =IF(A27="","",IF(A26=A27,B26+1,1)) -> 25 | C27: Apoc | D27: =IF(C27="","",IF(C27=C26,D26+1,1)) -> 25 | E27: Smite | F27: Apoc | G27: Psychic | L27: Use in the action phase. A friendly Psyker Tests. On a 2+, the closest enemy within 36” gets a blast marker. on a 7+, they get 2 blast markers instead.
A28: C | B28: =IF(A28="","",IF(A27=A28,B27+1,1)) -> 26 | C28: Orks | D28: =IF(C28="","",IF(C28=C27,D27+1,1)) -> 1 | E28: Ere We go! | F28: Orks | L28: Use when a detachment activates. Any units activate as if they were under the 'Assault' order, and can reroll wound rolls.
A29: C | B29: =IF(A29="","",IF(A28=A29,B28+1,1)) -> 27 | C29: Orks | D29: =IF(C29="","",IF(C29=C28,D28+1,1)) -> 2 | E29: Dakka! Dakka! Dakka! | F29: Orks | L29: Use in the action phase. Choose up to 3 Ork units in a Detachment lead by an Ork Commander. Rolls of 6s for ranged attacks cause 2 hits.
A30: C | B30: =IF(A30="","",IF(A29=A30,B29+1,1)) -> 28 | C30: Orks | D30: =IF(C30="","",IF(C30=C29,D29+1,1)) -> 3 | E30: Da Green Tide | F30: Orks | L30: Use in the Reinforcements Step. Select 1 destroyed friendly non-character light Ork unit that was destroyed and Roll a d12 and add 4. If it's more than the unit's Power, return it to the battlefield within 9” of a battlefield edge and 9” from enemy units, as its own detachment. Otherwise return this card to your hand and you can't use it this turn.
A31: C | B31: =IF(A31="","",IF(A30=A31,B30+1,1)) -> 29 | C31: Orks | D31: =IF(C31="","",IF(C31=C30,D30+1,1)) -> 4 | E31: Grot Shields | F31: Orks | L31: Use during the start of the damage Phase. 1 Ork light unit can move d3 blast markers to a gretchin unit within 6”.
A32: C | B32: =IF(A32="","",IF(A31=A32,B31+1,1)) -> 30 | C32: Orks | D32: =IF(C32="","",IF(C32=C31,D31+1,1)) -> 5 | E32: Brutal but Kunnin' | F32: Orks | L32: Use in the action phase. A single Ork Character gets +1 to hit and damage rolls, and a unit with 6” gets Stealth.
A33: C | B33: =IF(A33="","",IF(A32=A33,B32+1,1)) -> 31 | C33: Orks | D33: =IF(C33="","",IF(C33=C32,D32+1,1)) -> 6 | E33: Kunnin but Brutal | F33: Orks | L33: Use in the action phase. A single Ork Character gets stealth, and a unit with 6” gets +1 to hit and damage rolls.
A34: C | B34: =IF(A34="","",IF(A33=A34,B33+1,1)) -> 32 | C34: Orks | D34: =IF(C34="","",IF(C34=C33,D33+1,1)) -> 7 | E34: Da Krunch | F34: Orks | G34: Psychic | L34: Choose an enemy unit within 24” of an Ork Psyker. Roll a D12. On a 3+, the model gets 2 blast markers. On a 8+, the model gets 4 blast markers.
A35: C | B35: =IF(A35="","",IF(A34=A35,B34+1,1)) -> 33 | C35: Orks | D35: =IF(C35="","",IF(C35=C34,D34+1,1)) -> 8 | E35: Da Jump | F35: Orks | G35: Psychic | L35: Choose unit within 9” of an Ork Psyker. Roll a D12. On a 2+, move that unit anywhere on the battlefield further than 9” from enemy units.
A36: C | B36: =IF(A36="","",IF(A35=A36,B35+1,1)) -> 34 | C36: Orks | D36: =IF(C36="","",IF(C36=C35,D35+1,1)) -> 9 | E36: Warpath | F36: Orks | G36: Psychic | L36: Choose up to 3 light units within 12” of an Ork Psyker. Roll a D12. On a 2+, They perform a free fight action.
A37: C | B37: =IF(A37="","",IF(A36=A37,B36+1,1)) -> 35 | C37: Orks | D37: =IF(C37="","",IF(C37=C36,D36+1,1)) -> 10 | E37: Taktiks | F37: Blood Axes | L37: Use during the Action phase. Choose a detachment. Blood Axe units in that detachment can end within 1” of enemy units, and can shoot or fight, when they make a fall back move that phase.
A38: C | B38: =IF(A38="","",IF(A37=A38,B37+1,1)) -> 36 | C38: Orks | D38: =IF(C38="","",IF(C38=C37,D37+1,1)) -> 11 | E38: Da Old Ways | F38: Snakebites | L38: Use during the Damage phase. Snakebite Units in a single detachment get Ignore Damage (5+) ability.
A39: C | B39: =IF(A39="","",IF(A38=A39,B38+1,1)) -> 37 | C39: Orks | D39: =IF(C39="","",IF(C39=C38,D38+1,1)) -> 12 | E39: Kill-Kroozer Broadside | F39: Freebooterz | L39: Use in the Action Phase. Select a point visible to a friendly Freebooterz character. Roll a D12 for every unit within 6”. On a 7+, they get a blast marker. On an 11+, they take an additional blast marker. Light Characters subtract 3 from the roll.
A40: C | B40: =IF(A40="","",IF(A39=A40,B39+1,1)) -> 38 | C40: Orks | D40: =IF(C40="","",IF(C40=C39,D39+1,1)) -> 13 | E40: Speed Freeks | F40: Evil Sunz | L40: Use in Action Phase. Up to 3 Speed Freeks in a detachment can make 1 free move action.
A41: C | B41: =IF(A41="","",IF(A40=A41,B40+1,1)) -> 39 | C41: Orks | D41: =IF(C41="","",IF(C41=C40,D40+1,1)) -> 14 | E41: Armed To Da Teef | F41: Bad Moons | L41: Bad Moons Only. Use in Action Phase. Choose a detachment. Bad Moon units in that detachment can reroll hit rolls for attacks with ranged weapons.
A42: C | B42: =IF(A42="","",IF(A41=A42,B41+1,1)) -> 40 | C42: Orks | D42: =IF(C42="","",IF(C42=C41,D41+1,1)) -> 15 | E42: Proper Killy | F42: Goffs | L42: Goffs Only. Select 1 detachment. Their order is changed to 'Assault', and Goff units in that detachment add 1 to hit and wound rolls for melee attacks for Goff units in that detachment.
A43: C | B43: =IF(A43="","",IF(A42=A43,B42+1,1)) -> 41 | C43: Orks | D43: =IF(C43="","",IF(C43=C42,D42+1,1)) -> 16 | E43: Lucky Blue Gits | F43: Deathskulls | L43: Deathskulls Only. Choose a detachment. Until the end of the turn, Reroll 1s for hits and wound rolls, and reroll save rolls of 1 for Deathskulls in that detachment.
...

Sheet cards2
A1: Set | B1: Nm | C1: Fac | D1: Fac Nm | E1: Name | F1: Type | G1: SubType | H1: Cst | I1: Atk | J1: Life | K1: Sh | L1: Abilities1 | M1: Abilities2
A3: C2 | B3: =IF(A3="","",IF(A2=A3,B2+1,1)) -> 1 | C3: Knights | D3: =IF(C3="","",IF(C3=C2,D2+1,1)) -> 1 | E3: Rotate Ion Shields | F3: Knights | L3: Play in the damage phase. Remove 1 blast unit from an Imperial Knights or Chaos Knights unit.
A4: C2 | B4: =IF(A4="","",IF(A3=A4,B3+1,1)) -> 2 | C4: Knights | D4: =IF(C4="","",IF(C4=C3,D3+1,1)) -> 2 | E4: Full Tilt | F4: Knights | L4: Play in the action phase. Imperial Knights or Chaos Knights units in a detachment gain 6” to their Move.
A5: C2 | B5: =IF(A5="","",IF(A4=A5,B4+1,1)) -> 3 | C5: Knights | D5: =IF(C5="","",IF(C5=C4,D4+1,1)) -> 3 | E5: Thunderstomp | F5: Knights | L5: Use in an action phase. After an Imperial Knight or Chaos Knight unit fights, roll a D12 for each enemy light unit in base contact with it. On an 6+, that unit gets a blast marker.
A6: C2 | B6: =IF(A6="","",IF(A5=A6,B5+1,1)) -> 4 | C6: Knights | D6: =IF(C6="","",IF(C6=C5,D5+1,1)) -> 4 | E6: Devestating Attack | F6: Knights | L6: Use in the action phase. A single Imperial Knight or Chaos Knight unit gets +1 to hit and damage rolls in melee.
A7: C2 | B7: =IF(A7="","",IF(A6=A7,B6+1,1)) -> 5 | C7: Knights | D7: =IF(C7="","",IF(C7=C6,D6+1,1)) -> 5 | E7: Heirlooms of the Household | F7: Knights | L7: Search your deck for a Knight, Imperial Knight or Traitor Knight card, and then play it.
A8: C2 | B8: =IF(A8="","",IF(A7=A8,B7+1,1)) -> 6 | C8: Imperial Knights | D8: =IF(C8="","",IF(C8=C7,D7+1,1)) -> 1 | E8: Ion Aegis | F8: Imperial Knights | L8: Use in the damage phase. Chose an Imperial Knight. Imperial units within 6” of it gain Ignore Damage (6+) ability.
A9: C2 | B9: =IF(A9="","",IF(A8=A9,B8+1,1)) -> 7 | C9: Knights | D9: =IF(C9="","",IF(C9=C8,D8+1,1)) -> 1 | E9: Legendary Hero | F9: Freeblade | L9: Use in the action phase. A Freeblade unit can reroll hit and wound rolls.
A10: C2 | B10: =IF(A10="","",IF(A9=A10,B9+1,1)) -> 8 | C10: Imperial Knights | D10: =IF(C10="","",IF(C10=C9,D9+1,1)) -> 1 | E10: Benevolence of The Machine God | F10: Questor Mechanicus | L10: Use in the Order phase. A Questor Mechanicus unit can roll a d6 for each damage marker on it. On a 5+, remove 1 damage marker from that unit.
A11: C2 | B11: =IF(A11="","",IF(A10=A11,B10+1,1)) -> 9 | C11: Knights | D11: =IF(C11="","",IF(C11=C10,D10+1,1)) -> 1 | E11: Valiant Last Stand | F11: Questor Imperialis | L11: Use when a Questor Imperialis unit is destroyed. Before removing it, it makes a free shoot or fight action.
A12: C2 | B12: =IF(A12="","",IF(A11=A12,B11+1,1)) -> 10 | C12: Traitor Knights | D12: =IF(C12="","",IF(C12=C11,D11+1,1)) -> 1 | E12: The Traitor's Mark | F12: Questor Traitoris | L12: Use at the start of the damage phase. One Questor Traitoris unit gains the Terror Troops ability until the end of the phase. Then you may force the closest enemy unit within 6” of the Traitoris unit to make an immediate morale test.
A13: C2 | B13: =IF(A13="","",IF(A12=A13,B12+1,1)) -> 11 | C13: Imperial Knights | D13: =IF(C13="","",IF(C13=C12,D12+1,1)) -> 1 | E13: Glory of the Charge | F13: House Griffith | L13: Use before carrying out an order for a Detachment lead by a House Griffith Commander. The order is changed to Assault, and until the end of the phase, reroll missed hits for melee attacks for House Griffith units in that detachment.
A14: C2 | B14: =IF(A14="","",IF(A13=A14,B13+1,1)) -> 12 | C14: Imperial Knights | D14: =IF(C14="","",IF(C14=C13,D13+1,1)) -> 2 | E14: Gallant Warriors | F14: House Terryn | L14: Use in the action phase. House Terryn units in a detachment add 1 to their Attacks and hit rolls made with melee attacks, until the end of the phase.
... A21: C2 | B21: =IF(A21="","",IF(A20=A21,B20+1,1)) -> 19 | C21: Imperial Knights | D21: =IF(C21="","",IF(C21=C20,D20+1,1)) -> 9 | E21: Omnissiah's Grace | F21: House Taranis | L21: Use in the damage phase. Units in a House Taranis Detachment gain the Ignore Damage(5+) ability.
A22: C2 | B22: =IF(A22="","",IF(A21=A22,B21+1,1)) -> 20 | C22: Adeptus Mechanicus | D22: =IF(C22="","",IF(C22=C21,D21+1,1)) -> 1 | E22: Incantation of the Iron Soul | F22: Adeptus Mechanicus | G22: Canticle | L22: Play during the start of the Damage Phase. Adeptus Mechanicus units in a detachment automatically pass morale tests.
A23: C2 | B23: =IF(A23="","",IF(A22=A23,B22+1,1)) -> 21 | C23: Adeptus Mechanicus | D23: =IF(C23="","",IF(C23=C22,D22+1,1)) -> 2 | E23: Benediction of the Omnissiah | F23: Adeptus Mechanicus | G23: Canticle | L23: Play in any phase. One Adeptus Mechanic Detachment rolls D12s instead of D6s for ranged hit rolls until the end of the phase.
A24: C2 | B24: =IF(A24="","",IF(A23=A24,B23+1,1)) -> 22 | C24: Adeptus Mechanicus | D24: =IF(C24="","",IF(C24=C23,D23+1,1)) -> 3 | E24: Chant of the Remorseless Fist | F24: Adeptus Mechanicus | G24: Canticle | L24: Play in any phase. One Adeptus Mechanic Detachment rolls D12s instead of D6s for melee hit rolls until the end of the phase.
A25: C2 | B25: =IF(A25="","",IF(A24=A25,B24+1,1)) -> 23 | C25: Adeptus Mechanicus | D25: =IF(C25="","",IF(C25=C24,D24+1,1)) -> 4 | E25: Machine Spirits Revenge | F25: Adeptus Mechanicus | G25: Vehicle | L25: Play when an Adeptus Mechanicus Vehicle unit is destroyed. Roll a d6 for each unit within 6” of it. On a 4+, that unit gets a blast marker.
A26: C2 | B26: =IF(A26="","",IF(A25=A26,B25+1,1)) -> 24 | C26: Adeptus Mechanicus | D26: =IF(C26="","",IF(C26=C25,D25+1,1)) -> 5 | E26: Acquisition at Any Cost | F26: Adeptus Mechanicus | L26: Use in any phase. Adeptus Mechanicus units of a chosen detachment have Objective Secured ability until end of turn. This turn, an Adeptus Mechanicus Warlord in that detachment can roll a D12 instead of a D6 for one Armour Save roll.
A27: C2 | B27: =IF(A27="","",IF(A26=A27,B26+1,1)) -> 25 | C27: Adeptus Mechanicus | D27: =IF(C27="","",IF(C27=C26,D26+1,1)) -> 6 | E27: Litany of the Electromancer | F27: Adeptus Mechanicus | G27: Canticle | L27: Use in an action phase. Roll a D12 for each Adeptus Mechanicus unit of one detachment in base contact with an enemy unit. On an 8+, each enemy in base contact with that unit gts a blast marker.
A28: C2 | B28: =IF(A28="","",IF(A27=A28,B27+1,1)) -> 26 | C28: Adeptus Mechanicus | D28: =IF(C28="","",IF(C28=C27,D27+1,1)) -> 7 | E28: Protector Imperative | F28: Adeptus Mechanicus | G28: Skitarii | L28: Use in an action phase. 3 Skitarii units in your army may make a free shoot action.
A29: C2 | B29: =IF(A29="","",IF(A28=A29,B28+1,1)) -> 27 | C29: Adeptus Mechanicus | D29: =IF(C29="","",IF(C29=C28,D28+1,1)) -> 8 | E29: Machine Spirit Resurgent | F29: Adeptus Mechanicus | G29: Vehicle | L29: Use during the Damage phase. Mechanicus Vehicle Units in a single detachment get Ignore Damage (5+) ability.
A30: C2 | B30: =IF(A30="","",IF(A29=A30,B29+1,1)) -> 28 | C30: Adeptus Mechanicus | D30: =IF(C30="","",IF(C30=C29,D29+1,1)) -> 9 | E30: Gloria Mechanicus | F30: Adeptus Mechanicus | L30: Play at any time. Search your deck for a Canticle and play it.
A31: C2 | B31: =IF(A31="","",IF(A30=A31,B30+1,1)) -> 29 | C31: Adeptus Mechanicus | D31: =IF(C31="","",IF(C31=C30,D30+1,1)) -> 10 | E31: First-Hand Field Testing | F31: Ryza | L31: Use in the action phase. 1 Ryza Character in your army within 24” of an enemy unit rolls a d6. If the result is equal or greater than the Character's BS, place 2 blast markers on the enemy unit.
A32: C2 | B32: =IF(A32="","",IF(A31=A32,B31+1,1)) -> 30 | C32: Adeptus Mechanicus | D32: =IF(C32="","",IF(C32=C31,D31+1,1)) -> 11 | E32: Shroud Protocols | F32: Stygies VIII | L32: Use in the action phase. Stygies VIII units in a detachment are obscured targets.
A33: C2 | B33: =IF(A33="","",IF(A32=A33,B32+1,1)) -> 31 | C33: Adeptus Mechanicus | D33: =IF(C33="","",IF(C33=C32,D32+1,1)) -> 12 | E33: Staunch Defenders | F33: Agripinaa | L33: Use before carrying out an order for a Detachment lead by a Agripinaa Commander. The order is changed to Aimed Fire, and until the end of the phase, re-roll wound rolls of 1 for ranged attacks from Agripinaa units in that detachment.
A34: C2 | B34: =IF(A34="","",IF(A33=A34,B33+1,1)) -> 32 | C34: Adeptus Mechanicus | D34: =IF(C34="","",IF(C34=C33,D33+1,1)) -> 13 | E34: Legio Teleportarium | F34: Lucius | L34: Use in the action phase. Select 1 Lucius unit, remove it, and then set it up anywhere on the battlefield more than 9” from enemy units.
A35: C2 | B35: =IF(A35="","",IF(A34=A35,B34+1,1)) -> 33 | C35: Adeptus Mechanicus | D35: =IF(C35="","",IF(C35=C34,D34+1,1)) -> 14 | E35: Deafening Assault | F35: Metalica | L35: Use in the Damage Phase. 1 Metalica unit gains Terror Troops until the end of the phase.
A36: C2 | B36: =IF(A36="","",IF(A35=A36,B35+1,1)) -> 34 | C36: Adeptus Mechanicus | D36: =IF(C36="","",IF(C36=C35,D35+1,1)) -> 15 | E36: Refusal to Yield | F36: Graia | L36: Use in the Damage Phase. Graia units in an detachment gain the Ignore Damage(5+) ability until the end of the phase.
A37: C2 | B37: =IF(A37="","",IF(A36=A37,B36+1,1)) -> 35 | C37: Adeptus Mechanicus | D37: =IF(C37="","",IF(C37=C36,D36+1,1)) -> 16 | E37: Wrath of Mars | F37: Mars | L37: Use in the action phase. Marss units in a detachment can add 1 to wound rolls for ranged attacks.
A38: C2 | B38: =IF(A38="","",IF(A37=A38,B37+1,1)) -> 36 | C38: Sisters of Battle | D38: =IF(C38="","",IF(C38=C37,D37+1,1)) -> 1 | E38: Divine Guidance | F38: Sisters of Battle | L38: Play when you carry out an order. Until end of phase, roll D12s instead of D6s for ranged weapon hit rolls by Adeptus Sororitas in this detachment.
A39: C2 | B39: =IF(A39="","",IF(A38=A39,B38+1,1)) -> 37 | C39: Sisters of Battle | D39: =IF(C39="","",IF(C39=C38,D38+1,1)) -> 2 | E39: Spirit of the Martyr | F39: Sisters of Battle | G39: Infantry | L39: Play in the action phase. Roll a D12 for every Adeptus Sororitas Infantry unit in a detachment. on a 9+, remove 1 damage marker on that unit.
A40: C2 | B40: =IF(A40="","",IF(A39=A40,B39+1,1)) -> 38 | C40: Sisters of Battle | D40: =IF(C40="","",IF(C40=C39,D39+1,1)) -> 3 | E40: Light of the Emperor | F40: Sisters of Battle | L40: Play at the start of the damage phase. All Adeptus Sororitas units in 1 detachment automatically pass their morale tests.
A41: C2 | B41: =IF(A41="","",IF(A40=A41,B40+1,1)) -> 39 | C41: Sisters of Battle | D41: =IF(C41="","",IF(C41=C40,D40+1,1)) -> 4 | E41: Shield of Faith | F41: Sisters of Battle | L41: Play at the start of the Damage phase. One Adeptus Sororitas unit always rolls D12s when making saving rolls for this phase.
A42: C2 | B42: =IF(A42="","",IF(A41=A42,B41+1,1)) -> 40 | C42: Sisters of Battle | D42: =IF(C42="","",IF(C42=C41,D41+1,1)) -> 5 | E42: Purity of Faith | F42: Sisters of Battle | L42: Play if an enemy plays a psychic power asset within 36” of an Adeptus Sororitas unit. Roll a D12. on a 1-5, keep this card. On a 6+, that psychic power's effects are not resolved. Alternatively, discard this to reroll a hit roll.
A43: C2 | B43: =IF(A43="","",IF(A42=A43,B42+1,1)) -> 41 | C43: Sisters of Battle | D43: =IF(C43="","",IF(C43=C42,D42+1,1)) -> 6 | E43: Faith and Fury | F43: Sisters of Battle | L43: Play before an Adeptus Sororitas unit makes a shoot or fight action. Each hit counts as two hits instead of one.
A44: C2 | B44: =IF(A44="","",IF(A43=A44,B43+1,1)) -> 42 | C44: Sisters of Battle | D44: =IF(C44="","",IF(C44=C43,D43+1,1)) -> 7 | E44: The Passion | F44: Sisters of Battle | L44: Use before carrying out an order for a Detachment lead by a Adepta Sororitas Commander. The order is changed to Advance, and until the end of the phase, double the Move Characterstic for Adepta Sororitas units in that detachment.
A45: C2 | B45: =IF(A45="","",IF(A44=A45,B44+1,1)) -> 43 | C45: Sisters of Battle | D45: =IF(C45="","",IF(C45=C44,D44+1,1)) -> 8 | E45: Hand of the Emperor | F45: Sisters of Battle | L45: Play when you carry out an order. Add 1 to melee weapon attacks by Adepta Sororitas, or 2 for Adepta Sororitas characters.
A46: C2 | B46: =IF(A46="","",IF(A45=A46,B45+1,1)) -> 44 | C46: Sisters of Battle | D46: =IF(C46="","",IF(C46=C45,D45+1,1)) -> 9 | E46: Blood of Martyrs | F46: Our Martyred Lady | L46: Play when an Order of Our Martyred Lady warlord is destroyed. Each unit in the warlord's detachment may make a free shoot or fight action.
A47: C2 | B47: =IF(A47="","",IF(A46=A47,B46+1,1)) -> 45 | C47: Sisters of Battle | D47: =IF(C47="","",IF(C47=C46,D46+1,1)) -> 10 | E47: Daughters of the Emperor | F47: Ebon Chalice | L47: Play at the start of the Orders Phase. If you have an Order of the Ebon Chalice Warlord, draw 1 Sisters asset from your discard pile.
...

Sheet cards3
A1: Set | B1: Nm | C1: Fac | D1: Fac Nm | E1: Name | F1: Type | G1: SubType | H1: Cst | I1: Atk | J1: Life | K1: Sh | L1: Abilities1 | M1: Abilities2
A3: C3 | B3: =IF(A3="","",IF(A2=A3,B2+1,1)) -> 1 | C3: Chaos | D3: =IF(C3="","",IF(C3=C2,D2+1,1)) -> 1 | E3: Magical Boon | F3: Demons | L3: Use at any time. Look into your command deck, and draw a Daemonica Command Asset card that is a psychic power or a Deny the Witch card. Add that card to your hand, then shuffle the deck.
A4: C3 | B4: =IF(A4="","",IF(A3=A4,B3+1,1)) -> 2 | C4: Chaos | D4: =IF(C4="","",IF(C4=C3,D3+1,1)) -> 2 | E4: Warp Surge | F4: Demons | L4: Use when resolving damage to a Daemonica unit before saving throws are amde. Until the end of the phase, roll D12s for the saving throws, regardless of the blast marker size.
A5: C3 | B5: =IF(A5="","",IF(A4=A5,B4+1,1)) -> 3 | C5: Chaos | D5: =IF(C5="","",IF(C5=C4,D4+1,1)) -> 3 | E5: Denizens of the Warp | F5: Demons | L5: Use in the Reinforcement Step. Select a Daemonica Warlord, and Daemonica unit that has been destroyed. Roll a D12 and add 4. If it exceeds the Power rating of the destroyed unit, return it anywhere more than 9” from enemy units, as part of the Warlord's detachment. Otherwise return this card to your hand and you can't use it this turn.
A6: C3 | B6: =IF(A6="","",IF(A5=A6,B5+1,1)) -> 4 | C6: Chaos | D6: =IF(C6="","",IF(C6=C5,D5+1,1)) -> 4 | E6: Demonic Possession | F6: Demons | L6: Use when your opponent uses a psychic power, if at least one Daemonica unit is on the field. Roll a D12. If the result is greater than the leadership of the unit manifesting the power, place a damage marker next to it. If that destroys the unit, Roll a D12. On a 7+, replace that unit with a daemonica character less than the roll number as a new detachment.
A7: C3 | B7: =IF(A7="","",IF(A6=A7,B6+1,1)) -> 5 | C7: Chaos | D7: =IF(C7="","",IF(C7=C6,D6+1,1)) -> 5 | E7: Locus of Rage | F7: Khorne Demons | L7: Select a detachment led by a Daemonica Khorne Commander. The detachment's order is replaced with 'Assault', and roll D12s instead of D6s for hit rolls for attacks made by melee weapons for daemonica Khorne units for that phase.
A8: C3 | B8: =IF(A8="","",IF(A7=A8,B7+1,1)) -> 6 | C8: Chaos | D8: =IF(C8="","",IF(C8=C7,D7+1,1)) -> 6 | E8: Locus of Trickery | F8: Tzeentch Demons | L8: Use in the action phase. Select a detachment led by a Daemonica Tzeentch Commander. Until the end of the phase, Daemonica Tzeentch units in that detachment are obscured targets.
A9: C3 | B9: =IF(A9="","",IF(A8=A9,B8+1,1)) -> 7 | C9: Chaos | D9: =IF(C9="","",IF(C9=C8,D8+1,1)) -> 7 | E9: Locus of Virulence | F9: Nurgle Demons | L9: Use in the action phase. Select a detachment led by a Daemonica Nurgle Commander. Until the end of the phase, you can re-roll wound rolls for attacks made by Daemonica Nurgle units.
A10: C3 | B10: =IF(A10="","",IF(A9=A10,B9+1,1)) -> 8 | C10: Chaos | D10: =IF(C10="","",IF(C10=C9,D9+1,1)) -> 8 | E10: Locus of Swiftness | F10: Slannesh Demons | L10: Select a detachment led by a Daemonica Slaanesh Commander. The detachment's order is replaced with 'Assault', and Daemonica Slaanesh units in the detachment triple their move characteristic instead of doubling it, but cannot end in base contact with enemy units.
A11: C3 | B11: =IF(A11="","",IF(A10=A11,B10+1,1)) -> 9 | C11: Chaos | D11: =IF(C11="","",IF(C11=C10,D10+1,1)) -> 9 | E11: Wrath of Khorne | F11: Khorne Demons | L11: Use when an opponent uses a psychic power, before the effects are resolved, if you have a Khorne unit on the battlefield. Roll a D12 for the manifesting unit and every unit within 3” of it. On an 8+, place 2 blast markers next to the unit.
A12: C3 | B12: =IF(A12="","",IF(A11=A12,B11+1,1)) -> 10 | C12: Chaos | D12: =IF(C12="","",IF(C12=C11,D11+1,1)) -> 10 | E12: Cacophonic Choir | F12: Slannesh Demons | G12: Psychic | L12: Use in action phase. Choose one Daemonica Slaanesh Psyker unit and one enemy unit within 24” of the psyker. Roll a D12. If the result is less than the enemy's unit's Leadership, place 1 blast marker next to it. If it is equal or greater, place 2 blast markers next to it.
A13: C3 | B13: =IF(A13="","",IF(A12=A13,B12+1,1)) -> 11 | C13: Chaos | D13: =IF(C13="","",IF(C13=C12,D12+1,1)) -> 11 | E13: Stream of Corruption | F13: Nurgle Demons | G13: Psychic | L13: Use in the action Phase. Choose one Daemonica Nurgle Psyker unit and an enemy unit within 12” of the psyker. Roll a D12. On a 4-7, place 2 blast markers next to it. On an 8-10, place 3 blast markers, and on an 11+, place 4 blast markers.
A14: C3 | B14: =IF(A14="","",IF(A13=A14,B13+1,1)) -> 12 | C14: Chaos | D14: =IF(C14="","",IF(C14=C13,D13+1,1)) -> 12 | E14: Infernal Gateway | F14: Tzeentch Demons | G14: Psychic | L14: Use in action phase. Select a Daemonica Tzeentch Psyker and one point on the battlefield within 24” of the Psyker. Roll a D12 for each unit within 6” of that point, subtracting 1 if it is a light Character. On a 6+, place a blast marker next to it.
A15: C3 | B15: =IF(A15="","",IF(A14=A15,B14+1,1)) -> 13 | C15: Chaos | D15: =IF(C15="","",IF(C15=C14,D14+1,1)) -> 13 | E15: Gaze of Fate | F15: Tzeentch Demons | G15: Psychic | L15: Use at end of Orders Phase. Select a Tzeentch Psyker. Roll a D12. On a 2+, Choose an opponent to Look at their Command Asset Cards, then draw a Command Card.
A16: C3 | B16: =IF(A16="","",IF(A15=A16,B15+1,1)) -> 14 | C16: Chaos | D16: =IF(C16="","",IF(C16=C15,D15+1,1)) -> 14 | E16: Aura of Acquiescence | F16: Slannesh Demons | L16: Use in Action Phase. Select a Daemonica Slaanesh unit. Until the end of the phase, the Attacks characteristic in base contact with it is halved.
A17: C3 | B17: =IF(A17="","",IF(A16=A17,B16+1,1)) -> 15 | C17: Chaos | D17: =IF(C17="","",IF(C17=C16,D16+1,1)) -> 15 | E17: Frenetic Bloodlust | F17: Khorne Demons | L17: Use in Action Phase. Select a Daemonica Khorne unit. That unit makes 2 free fight actions back-to-back.
A18: C3 | B18: =IF(A18="","",IF(A17=A18,B17+1,1)) -> 16 | C18: Chaos | D18: =IF(C18="","",IF(C18=C17,D17+1,1)) -> 16 | E18: Revolting Regeneration | F18: Nurgle Demons | L18: Use in Action Phase. Select a Daemonica Nurgle detachment. Remove up to D3 damage markers from that unit.
A19: C3 | B19: =IF(A19="","",IF(A18=A19,B18+1,1)) -> 17 | C19: Chaos | D19: =IF(C19="","",IF(C19=C18,D18+1,1)) -> 17 | E19: Gift of Chaos | F19: Chaos | G19: Psychic | L19: Use in the action phase. Pick the closest non-character light unit of 5 within 18” to a psyker. Roll a d12. On a 1-9, place a blast marker on that unit. On a 10+, place 2 blast markers on that unit, and place a chaos spawn next to it. The Spawn is part of the Psyker's detachment.
A20: C3 | B20: =IF(A20="","",IF(A19=A20,B19+1,1)) -> 18 | C20: Chaos | D20: =IF(C20="","",IF(C20=C19,D19+1,1)) -> 18 | E20: Bolt of Change | F20: Tzeentch | G20: Psychic | L20: Use in the action phase. Pick a Tzeentch Psyker to manifest, then select a light character within 18” and roll 2d6. If it is less than the character's power rating, place a blast marker next to it. Otherwise, immediately destroy it and replace it with a chaos spawn unit, as part of the Psyker's detachment.
A21: C3 | B21: =IF(A21="","",IF(A20=A21,B20+1,1)) -> 19 | C21: Chaos | D21: =IF(C21="","",IF(C21=C20,D20+1,1)) -> 19 | E21: Fury of Khorne | F21: Khorne | L21: Choose a Khorne character. Add +2 to its attacks and damage rolls for this character this turn.
A22: C3 | B22: =IF(A22="","",IF(A21=A22,B21+1,1)) -> 20 | C22: Chaos | D22: =IF(C22="","",IF(C22=C21,D21+1,1)) -> 20 | E22: Delightful Agonies | F22: Slannesh | G22: Psychic | L22: Use in the action phase. Choose a Slaanesh Psyker and one slaanesh unit with 36” of each other. Until the end of the turn, that unit ignores penalties for critical damage, and add 1 to attacks for each damage marker next to it.
A23: C3 | B23: =IF(A23="","",IF(A22=A23,B22+1,1)) -> 21 | C23: Chaos | D23: =IF(C23="","",IF(C23=C22,D22+1,1)) -> 21 | E23: Plague Wind | F23: Nurgle | G23: Psychic | L23: Use in the action phase. Choose a Nurgle Psyker and roll a D12. On a 2+, place a blast marker next to the closest enemy within 18” to the psyker. Then roll a D12” for every other unit within 6” of that unit. On a 7+, place a blast marker nexto that unit.
A24: C3 | B24: =IF(A24="","",IF(A23=A24,B23+1,1)) -> 22 | C24: Tau | D24: =IF(C24="","",IF(C24=C23,D23+1,1)) -> 1 | E24: Markerlights | F24: Tau | L24: Use in the action phase. Select 1 enemy detachment. Reroll to-hit rolls of 1 from ranged weapons by Tau units against the units in that detachment.
A25: C3 | B25: =IF(A25="","",IF(A24=A25,B24+1,1)) -> 23 | C25: Tau | D25: =IF(C25="","",IF(C25=C24,D24+1,1)) -> 2 | E25: Saviour Protocols | F25: Tau | L25: Use at the start of the damage phase. One Tau unit within 6” of a friendly T'au Empire Drones unit, they may remove up to D3 blast markers from that unit and place it on the Drones instead.
A26: C3 | B26: =IF(A26="","",IF(A25=A26,B25+1,1)) -> 24 | C26: Tau | D26: =IF(C26="","",IF(C26=C25,D25+1,1)) -> 3 | E26: Kauyon | F26: Tau | L26: Use when your oponnent selects one of their detachments to carry out an order. One of your detachments led by a Tau Commander that has not carried out their order replaces their order with Aimed Fire, and then carries out that order before the enemy detachment.
A27: C3 | B27: =IF(A27="","",IF(A26=A27,B26+1,1)) -> 25 | C27: Tau | D27: =IF(C27="","",IF(C27=C26,D26+1,1)) -> 4 | E27: Coordinated Fire Arcs | F27: Tau | G27: Tau Sept | L27: Use in the Action phase. Select 1 detachment led by a a Tau Sept Commander. Until the end of the phase, when an enemy unit moves in base contact of a Tau Sept in that detachment, that Tau Sept unit may make a free shoot action, targeting the enemy that moved into base contact, as if they were not in base contact.
A28: C3 | B28: =IF(A28="","",IF(A27=A28,B27+1,1)) -> 26 | C28: Tau | D28: =IF(C28="","",IF(C28=C27,D27+1,1)) -> 5 | E28: Focus Fire | F28: Tau | G28: Tau Sept | L28: Use in the Action phase. Select an enemy unit and a Tau detachment. Reroll wound rolls for attacks by ranged weapons by Tau Sept units in that detachment that target that unit until the end of this turn.
A29: C3 | B29: =IF(A29="","",IF(A28=A29,B28+1,1)) -> 27 | C29: Tau | D29: =IF(C29="","",IF(C29=C28,D28+1,1)) -> 6 | E29: Mont'ka | F29: Tau | L29: Use when your opponent selects 1 detachment to carry out an order. One detachment lead by a Tau Commander that hasn't carried out its order replaced their order with Advance, and carries out its order before your opponent does so.
A30: C3 | B30: =IF(A30="","",IF(A29=A30,B29+1,1)) -> 28 | C30: Tau | D30: =IF(C30="","",IF(C30=C29,D29+1,1)) -> 7 | E30: Seeker Missiles | F30: Tau | G30: Vehicles | L30: Use when a Tau Vehicle makes a shoot action. Select an enemy visible to that vehicle and roll a d6. On e a 2+, place a blast marker next to that unit. If the enemy was a Heavy or Super-Heavy, place 2 blast markers instead.
A31: C3 | B31: =IF(A31="","",IF(A30=A31,B30+1,1)) -> 29 | C31: Tau | D31: =IF(C31="","",IF(C31=C30,D30+1,1)) -> 8 | E31: Invocation of the Elements | F31: Tau | G31: Ethereal | L31: Use in the Action phase. When used, select one Tau Ethereal unit. Until the end of the turn, add 1 to hit and wound rolls by Tau units within 6” of the Ethereal unit, and add 1 to saving throws for Tau units within 6” of that Ethereal unit.
A32: C3 | B32: =IF(A32="","",IF(A31=A32,B31+1,1)) -> 30 | C32: Tau | D32: =IF(C32="","",IF(C32=C31,D31+1,1)) -> 9 | E32: Early Warning Overrides | F32: Tau | G32: Battlesuit | L32: Use in the Set up Reinforcements step, after an enemy has set up an enemy unit that phase. One Tau Battlesuit makes a free shoot action against that enemy unit.
A33: C3 | B33: =IF(A33="","",IF(A32=A33,B32+1,1)) -> 31 | C33: Tau | D33: =IF(C33="","",IF(C33=C32,D32+1,1)) -> 10 | E33: Calm Discipline | F33: Sa'cea | L33: Select a detachment led by a Sa'cea Sept Commander. The detachment's order is replaced with 'Advance', and Sa'cea Sept units in the detachment add 1 to hit rolls with ranged weapons, and 2 to their leadership characterstic, until the end of their turn.
A34: C3 | B34: =IF(A34="","",IF(A33=A34,B33+1,1)) -> 32 | C34: Tau | D34: =IF(C34="","",IF(C34=C33,D33+1,1)) -> 11 | E34: Adaptive Camoflage | F34: Dal'yth | L34: Use in the action phase. Select a detachment lead by a Dal'yth Sept Commander. Until the end of the turn, Dal'yth Sept units in that detachment are obscured targets.
A35: C3 | B35: =IF(A35="","",IF(A34=A35,B34+1,1)) -> 33 | C35: Tau | D35: =IF(C35="","",IF(C35=C34,D34+1,1)) -> 12 | E35: Drop Zone Clearance | F35: Farsight Enclaves | L35: Use in the Set up Reinforcements step. Up to 3 Farsight Enclaves Battlesuit units that were set up this phase make make 1 free shoot action.
A36: C3 | B36: =IF(A36="","",IF(A35=A36,B35+1,1)) -> 34 | C36: Tau | D36: =IF(C36="","",IF(C36=C35,D35+1,1)) -> 13 | E36: Superior Craftsmanship | F36: Bork'an | L36: Use in the Action phase. Select a detachment lead by a Bork'an Commander. Until the end of the turn, add 6” to the Range of ranged weapons for Bork'an Sept units, or 12” if they are performing the Aim Fire order.
A37: C3 | B37: =IF(A37="","",IF(A36=A37,B36+1,1)) -> 35 | C37: Tau | D37: =IF(C37="","",IF(C37=C36,D36+1,1)) -> 14 | E37: Strike Fast | F37: Vior'la | L37: Select a detachment led by a Vior'la Sept Commander. The detachment's order is replaced with 'Advance', and Vior'la Sept units in the detachment double their Move is doubled until the end of turn..
A38: C3 | B38: =IF(A38="","",IF(A37=A38,B37+1,1)) -> 36 | C38: Genestealer Cults | D38: =IF(C38="","",IF(C38=C37,D37+1,1)) -> 1 | E38: Concealed Explosives | F38: Genestealer Cults | G38: Warlord | L38: Use in the Action Phase. Select D3 points within 18” of a Genstealer Cults Warlord. Roll a D12 for each unit within 6” of those points, subtracting 2 from rolls if they are a Light Character, and 2 to the roll if they are Super-Heavy or Garrisoning Defensible Terrain. On an 8+, place a blast marker next to the unit.
A39: C3 | B39: =IF(A39="","",IF(A38=A39,B38+1,1)) -> 37 | C39: Genestealer Cults | D39: =IF(C39="","",IF(C39=C38,D38+1,1)) -> 2 | E39: Unquestioning Loyalty | F39: Genestealer Cults | G39: Character | L39: Use at the start of the Damage phase. Select a Genestealer Cults Character that has blast markers on it. Move up to 3 blast markers to a friendly Genestealer Cults Light unit within 6”.
A40: C3 | B40: =IF(A40="","",IF(A39=A40,B39+1,1)) -> 38 | C40: Genestealer Cults | D40: =IF(C40="","",IF(C40=C39,D39+1,1)) -> 3 | E40: A Perfect Ambush | F40: Genestealer Cults | G40: Light | L40: Use in the Reinforcements Step. Select a Genestealer Cults Light unit that was destroyed and roll a D12. If the result was equal or above the power of the unit, set up that unit anywhere on the battlefield, and 9” from any enemy units. If you roll below the power of the unit, put this card back into your hand instead of discarding it.
A41: C3 | B41: =IF(A41="","",IF(A40=A41,B40+1,1)) -> 39 | C41: Genestealer Cults | D41: =IF(C41="","",IF(C41=C40,D40+1,1)) -> 4 | E41: Lurk in the Shadows | F41: Genestealer Cults | L41: Use in the Action Phase. Select a Genstealer Cults detachment. Until the end of the turn, Genestealer Cults in that detachment are Obscured targets.
...

Sheet pages
C1: pg | D1: 1 | E1: 2 | F1: 3 | G1: 4 | H1: 5 | I1: 6 | J1: 7 | K1: 8 | L1: 9
B3: C | C3: =IF(EQ(B3,B2),C2+1,1) -> 1 | D3: =CONCATENATE("card-",$B3,"-",($C3-1)*9+D$1) -> card-C-1 | E3: =CONCATENATE("card-",$B3,"-",($C3-1)*9+E$1) -> card-C-2 | F3: =CONCATENATE("card-",$B3,"-",($C3-1)*9+F$1) -> card-C-3 | G3: =CONCATENATE("card-",$B3,"-",($C3-1)*9+G$1) -> card-C-4 | H3: =CONCATENATE("card-",$B3,"-",($C3-1)*9+H$1) -> card-C-5 | I3: =CONCATENATE("card-",$B3,"-",($C3-1)*9+I$1) -> card-C-6 | J3: =CONCATENATE("card-",$B3,"-",($C3-1)*9+J$1) -> card-C-7 | K3: =CONCATENATE("card-",$B3,"-",($C3-1)*9+K$1) -> card-C-8 | L3: =CONCATENATE("card-",$B3,"-",($C3-1)*9+L$1) -> card-C-9
B4: C | C4: =IF(EQ(B4,B3),C3+1,1) -> 2 | D4: =CONCATENATE("card-",$B4,"-",($C4-1)*9+D$1) -> card-C-10 | E4: =CONCATENATE("card-",$B4,"-",($C4-1)*9+E$1) -> card-C-11 | F4: =CONCATENATE("card-",$B4,"-",($C4-1)*9+F$1) -> card-C-12 | G4: =CONCATENATE("card-",$B4,"-",($C4-1)*9+G$1) -> card-C-13 | H4: =CONCATENATE("card-",$B4,"-",($C4-1)*9+H$1) -> card-C-14 | I4: =CONCATENATE("card-",$B4,"-",($C4-1)*9+I$1) -> card-C-15 | J4: =CONCATENATE("card-",$B4,"-",($C4-1)*9+J$1) -> card-C-16 | K4: =CONCATENATE("card-",$B4,"-",($C4-1)*9+K$1) -> card-C-17 | L4: =CONCATENATE("card-",$B4,"-",($C4-1)*9+L$1) -> card-C-18
B5: C | C5: =IF(EQ(B5,B4),C4+1,1) -> 3 | D5: =CONCATENATE("card-",$B5,"-",($C5-1)*9+D$1) -> card-C-19 | E5: =CONCATENATE("card-",$B5,"-",($C5-1)*9+E$1) -> card-C-20 | F5: =CONCATENATE("card-",$B5,"-",($C5-1)*9+F$1) -> card-C-21 | G5: =CONCATENATE("card-",$B5,"-",($C5-1)*9+G$1) -> card-C-22 | H5: =CONCATENATE("card-",$B5,"-",($C5-1)*9+H$1) -> card-C-23 | I5: =CONCATENATE("card-",$B5,"-",($C5-1)*9+I$1) -> card-C-24 | J5: =CONCATENATE("card-",$B5,"-",($C5-1)*9+J$1) -> card-C-25 | K5: =CONCATENATE("card-",$B5,"-",($C5-1)*9+K$1) -> card-C-26 | L5: =CONCATENATE("card-",$B5,"-",($C5-1)*9+L$1) -> card-C-27
B6: C | C6: =IF(EQ(B6,B5),C5+1,1) -> 4 | D6: =CONCATENATE("card-",$B6,"-",($C6-1)*9+D$1) -> card-C-28 | E6: =CONCATENATE("card-",$B6,"-",($C6-1)*9+E$1) -> card-C-29 | F6: =CONCATENATE("card-",$B6,"-",($C6-1)*9+F$1) -> card-C-30 | G6: =CONCATENATE("card-",$B6,"-",($C6-1)*9+G$1) -> card-C-31 | H6: =CONCATENATE("card-",$B6,"-",($C6-1)*9+H$1) -> card-C-32 | I6: =CONCATENATE("card-",$B6,"-",($C6-1)*9+I$1) -> card-C-33 | J6: =CONCATENATE("card-",$B6,"-",($C6-1)*9+J$1) -> card-C-34 | K6: =CONCATENATE("card-",$B6,"-",($C6-1)*9+K$1) -> card-C-35 | L6: =CONCATENATE("card-",$B6,"-",($C6-1)*9+L$1) -> card-C-36
B7: C | C7: =IF(EQ(B7,B6),C6+1,1) -> 5 | D7: =CONCATENATE("card-",$B7,"-",($C7-1)*9+D$1) -> card-C-37 | E7: =CONCATENATE("card-",$B7,"-",($C7-1)*9+E$1) -> card-C-38 | F7: =CONCATENATE("card-",$B7,"-",($C7-1)*9+F$1) -> card-C-39 | G7: =CONCATENATE("card-",$B7,"-",($C7-1)*9+G$1) -> card-C-40 | H7: =CONCATENATE("card-",$B7,"-",($C7-1)*9+H$1) -> card-C-41 | I7: =CONCATENATE("card-",$B7,"-",($C7-1)*9+I$1) -> card-C-42 | J7: =CONCATENATE("card-",$B7,"-",($C7-1)*9+J$1) -> card-C-43 | K7: =CONCATENATE("card-",$B7,"-",($C7-1)*9+K$1) -> card-C-44 | L7: =CONCATENATE("card-",$B7,"-",($C7-1)*9+L$1) -> card-C-45
B8: C | C8: =IF(EQ(B8,B7),C7+1,1) -> 6 | D8: =CONCATENATE("card-",$B8,"-",($C8-1)*9+D$1) -> card-C-46 | E8: =CONCATENATE("card-",$B8,"-",($C8-1)*9+E$1) -> card-C-47 | F8: =CONCATENATE("card-",$B8,"-",($C8-1)*9+F$1) -> card-C-48 | G8: =CONCATENATE("card-",$B8,"-",($C8-1)*9+G$1) -> card-C-49 | H8: =CONCATENATE("card-",$B8,"-",($C8-1)*9+H$1) -> card-C-50 | I8: =CONCATENATE("card-",$B8,"-",($C8-1)*9+I$1) -> card-C-51 | J8: =CONCATENATE("card-",$B8,"-",($C8-1)*9+J$1) -> card-C-52 | K8: =CONCATENATE("card-",$B8,"-",($C8-1)*9+K$1) -> card-C-53 | L8: =CONCATENATE("card-",$B8,"-",($C8-1)*9+L$1) -> card-C-54
B9: C | C9: =IF(EQ(B9,B8),C8+1,1) -> 7 | D9: =CONCATENATE("card-",$B9,"-",($C9-1)*9+D$1) -> card-C-55 | E9: =CONCATENATE("card-",$B9,"-",($C9-1)*9+E$1) -> card-C-56 | F9: =CONCATENATE("card-",$B9,"-",($C9-1)*9+F$1) -> card-C-57 | G9: =CONCATENATE("card-",$B9,"-",($C9-1)*9+G$1) -> card-C-58 | H9: =CONCATENATE("card-",$B9,"-",($C9-1)*9+H$1) -> card-C-59 | I9: =CONCATENATE("card-",$B9,"-",($C9-1)*9+I$1) -> card-C-60 | J9: =CONCATENATE("card-",$B9,"-",($C9-1)*9+J$1) -> card-C-61 | K9: =CONCATENATE("card-",$B9,"-",($C9-1)*9+K$1) -> card-C-62 | L9: =CONCATENATE("card-",$B9,"-",($C9-1)*9+L$1) -> card-C-63
B10: C | C10: =IF(EQ(B10,B9),C9+1,1) -> 8 | D10: =CONCATENATE("card-",$B10,"-",($C10-1)*9+D$1) -> card-C-64 | E10: =CONCATENATE("card-",$B10,"-",($C10-1)*9+E$1) -> card-C-65 | F10: =CONCATENATE("card-",$B10,"-",($C10-1)*9+F$1) -> card-C-66 | G10: =CONCATENATE("card-",$B10,"-",($C10-1)*9+G$1) -> card-C-67 | H10: =CONCATENATE("card-",$B10,"-",($C10-1)*9+H$1) -> card-C-68 | I10: =CONCATENATE("card-",$B10,"-",($C10-1)*9+I$1) -> card-C-69 | J10: =CONCATENATE("card-",$B10,"-",($C10-1)*9+J$1) -> card-C-70 | K10: =CONCATENATE("card-",$B10,"-",($C10-1)*9+K$1) -> card-C-71 | L10: =CONCATENATE("card-",$B10,"-",($C10-1)*9+L$1) -> card-C-72
B11: C | C11: =IF(EQ(B11,B10),C10+1,1) -> 9 | D11: =CONCATENATE("card-",$B11,"-",($C11-1)*9+D$1) -> card-C-73 | E11: =CONCATENATE("card-",$B11,"-",($C11-1)*9+E$1) -> card-C-74 | F11: =CONCATENATE("card-",$B11,"-",($C11-1)*9+F$1) -> card-C-75 | G11: =CONCATENATE("card-",$B11,"-",($C11-1)*9+G$1) -> card-C-76 | H11: =CONCATENATE("card-",$B11,"-",($C11-1)*9+H$1) -> card-C-77 | I11: =CONCATENATE("card-",$B11,"-",($C11-1)*9+I$1) -> card-C-78 | J11: =CONCATENATE("card-",$B11,"-",($C11-1)*9+J$1) -> card-C-79 | K11: =CONCATENATE("card-",$B11,"-",($C11-1)*9+K$1) -> card-C-80 | L11: =CONCATENATE("card-",$B11,"-",($C11-1)*9+L$1) -> card-C-81
B12: C | C12: =IF(EQ(B12,B11),C11+1,1) -> 10 | D12: =CONCATENATE("card-",$B12,"-",($C12-1)*9+D$1) -> card-C-82 | E12: =CONCATENATE("card-",$B12,"-",($C12-1)*9+E$1) -> card-C-83 | F12: =CONCATENATE("card-",$B12,"-",($C12-1)*9+F$1) -> card-C-84 | G12: =CONCATENATE("card-",$B12,"-",($C12-1)*9+G$1) -> card-C-85 | H12: =CONCATENATE("card-",$B12,"-",($C12-1)*9+H$1) -> card-C-86 | I12: =CONCATENATE("card-",$B12,"-",($C12-1)*9+I$1) -> card-C-87 | J12: =CONCATENATE("card-",$B12,"-",($C12-1)*9+J$1) -> card-C-88 | K12: =CONCATENATE("card-",$B12,"-",($C12-1)*9+K$1) -> card-C-89 | L12: =CONCATENATE("card-",$B12,"-",($C12-1)*9+L$1) -> card-C-90
B13: C | C13: =IF(EQ(B13,B12),C12+1,1) -> 11 | D13: =CONCATENATE("card-",$B13,"-",($C13-1)*9+D$1) -> card-C-91 | E13: =CONCATENATE("card-",$B13,"-",($C13-1)*9+E$1) -> card-C-92 | F13: =CONCATENATE("card-",$B13,"-",($C13-1)*9+F$1) -> card-C-93 | G13: =CONCATENATE("card-",$B13,"-",($C13-1)*9+G$1) -> card-C-94 | H13: =CONCATENATE("card-",$B13,"-",($C13-1)*9+H$1) -> card-C-95 | I13: =CONCATENATE("card-",$B13,"-",($C13-1)*9+I$1) -> card-C-96 | J13: =CONCATENATE("card-",$B13,"-",($C13-1)*9+J$1) -> card-C-97 | K13: =CONCATENATE("card-",$B13,"-",($C13-1)*9+K$1) -> card-C-98 | L13: =CONCATENATE("card-",$B13,"-",($C13-1)*9+L$1) -> card-C-99
B14: C | C14: =IF(EQ(B14,B13),C13+1,1) -> 12 | D14: =CONCATENATE("card-",$B14,"-",($C14-1)*9+D$1) -> card-C-100 | E14: =CONCATENATE("card-",$B14,"-",($C14-1)*9+E$1) -> card-C-101 | F14: =CONCATENATE("card-",$B14,"-",($C14-1)*9+F$1) -> card-C-102 | G14: =CONCATENATE("card-",$B14,"-",($C14-1)*9+G$1) -> card-C-103 | H14: =CONCATENATE("card-",$B14,"-",($C14-1)*9+H$1) -> card-C-104 | I14: =CONCATENATE("card-",$B14,"-",($C14-1)*9+I$1) -> card-C-105 | J14: =CONCATENATE("card-",$B14,"-",($C14-1)*9+J$1) -> card-C-106 | K14: =CONCATENATE("card-",$B14,"-",($C14-1)*9+K$1) -> card-C-107 | L14: =CONCATENATE("card-",$B14,"-",($C14-1)*9+L$1) -> card-C-108
B15: C | C15: =IF(EQ(B15,B14),C14+1,1) -> 13 | D15: =CONCATENATE("card-",$B15,"-",($C15-1)*9+D$1) -> card-C-109 | E15: =CONCATENATE("card-",$B15,"-",($C15-1)*9+E$1) -> card-C-110 | F15: =CONCATENATE("card-",$B15,"-",($C15-1)*9+F$1) -> card-C-111 | G15: =CONCATENATE("card-",$B15,"-",($C15-1)*9+G$1) -> card-C-112 | H15: =CONCATENATE("card-",$B15,"-",($C15-1)*9+H$1) -> card-C-113 | I15: =CONCATENATE("card-",$B15,"-",($C15-1)*9+I$1) -> card-C-114 | J15: =CONCATENATE("card-",$B15,"-",($C15-1)*9+J$1) -> card-C-115 | K15: =CONCATENATE("card-",$B15,"-",($C15-1)*9+K$1) -> card-C-116 | L15: =CONCATENATE("card-",$B15,"-",($C15-1)*9+L$1) -> card-C-117
B16: C | C16: =IF(EQ(B16,B15),C15+1,1) -> 14 | D16: =CONCATENATE("card-",$B16,"-",($C16-1)*9+D$1) -> card-C-118 | E16: Blank | F16: Blank | G16: Blank | H16: Blank | I16: Blank | J16: Blank | K16: Blank | L16: Blank
B17: C2 | C17: =IF(EQ(B17,B16),C16+1,1) -> 1 | D17: =CONCATENATE("card-",$B17,"-",($C17-1)*9+D$1) -> card-C2-1 | E17: =CONCATENATE("card-",$B17,"-",($C17-1)*9+E$1) -> card-C2-2 | F17: =CONCATENATE("card-",$B17,"-",($C17-1)*9+F$1) -> card-C2-3 | G17: =CONCATENATE("card-",$B17,"-",($C17-1)*9+G$1) -> card-C2-4 | H17: =CONCATENATE("card-",$B17,"-",($C17-1)*9+H$1) -> card-C2-5 | I17: =CONCATENATE("card-",$B17,"-",($C17-1)*9+I$1) -> card-C2-6 | J17: =CONCATENATE("card-",$B17,"-",($C17-1)*9+J$1) -> card-C2-7 | K17: =CONCATENATE("card-",$B17,"-",($C17-1)*9+K$1) -> card-C2-8 | L17: =CONCATENATE("card-",$B17,"-",($C17-1)*9+L$1) -> card-C2-9
B18: C2 | C18: =IF(EQ(B18,B17),C17+1,1) -> 2 | D18: =CONCATENATE("card-",$B18,"-",($C18-1)*9+D$1) -> card-C2-10 | E18: =CONCATENATE("card-",$B18,"-",($C18-1)*9+E$1) -> card-C2-11 | F18: =CONCATENATE("card-",$B18,"-",($C18-1)*9+F$1) -> card-C2-12 | G18: =CONCATENATE("card-",$B18,"-",($C18-1)*9+G$1) -> card-C2-13 | H18: =CONCATENATE("card-",$B18,"-",($C18-1)*9+H$1) -> card-C2-14 | I18: =CONCATENATE("card-",$B18,"-",($C18-1)*9+I$1) -> card-C2-15 | J18: =CONCATENATE("card-",$B18,"-",($C18-1)*9+J$1) -> card-C2-16 | K18: =CONCATENATE("card-",$B18,"-",($C18-1)*9+K$1) -> card-C2-17 | L18: =CONCATENATE("card-",$B18,"-",($C18-1)*9+L$1) -> card-C2-18
B19: C2 | C19: =IF(EQ(B19,B18),C18+1,1) -> 3 | D19: =CONCATENATE("card-",$B19,"-",($C19-1)*9+D$1) -> card-C2-19 | E19: =CONCATENATE("card-",$B19,"-",($C19-1)*9+E$1) -> card-C2-20 | F19: =CONCATENATE("card-",$B19,"-",($C19-1)*9+F$1) -> card-C2-21 | G19: =CONCATENATE("card-",$B19,"-",($C19-1)*9+G$1) -> card-C2-22 | H19: =CONCATENATE("card-",$B19,"-",($C19-1)*9+H$1) -> card-C2-23 | I19: =CONCATENATE("card-",$B19,"-",($C19-1)*9+I$1) -> card-C2-24 | J19: =CONCATENATE("card-",$B19,"-",($C19-1)*9+J$1) -> card-C2-25 | K19: =CONCATENATE("card-",$B19,"-",($C19-1)*9+K$1) -> card-C2-26 | L19: =CONCATENATE("card-",$B19,"-",($C19-1)*9+L$1) -> card-C2-27
B20: C2 | C20: =IF(EQ(B20,B19),C19+1,1) -> 4 | D20: =CONCATENATE("card-",$B20,"-",($C20-1)*9+D$1) -> card-C2-28 | E20: =CONCATENATE("card-",$B20,"-",($C20-1)*9+E$1) -> card-C2-29 | F20: =CONCATENATE("card-",$B20,"-",($C20-1)*9+F$1) -> card-C2-30 | G20: =CONCATENATE("card-",$B20,"-",($C20-1)*9+G$1) -> card-C2-31 | H20: =CONCATENATE("card-",$B20,"-",($C20-1)*9+H$1) -> card-C2-32 | I20: =CONCATENATE("card-",$B20,"-",($C20-1)*9+I$1) -> card-C2-33 | J20: =CONCATENATE("card-",$B20,"-",($C20-1)*9+J$1) -> card-C2-34 | K20: =CONCATENATE("card-",$B20,"-",($C20-1)*9+K$1) -> card-C2-35 | L20: =CONCATENATE("card-",$B20,"-",($C20-1)*9+L$1) -> card-C2-36
B21: C2 | C21: =IF(EQ(B21,B20),C20+1,1) -> 5 | D21: =CONCATENATE("card-",$B21,"-",($C21-1)*9+D$1) -> card-C2-37 | E21: =CONCATENATE("card-",$B21,"-",($C21-1)*9+E$1) -> card-C2-38 | F21: =CONCATENATE("card-",$B21,"-",($C21-1)*9+F$1) -> card-C2-39 | G21: =CONCATENATE("card-",$B21,"-",($C21-1)*9+G$1) -> card-C2-40 | H21: =CONCATENATE("card-",$B21,"-",($C21-1)*9+H$1) -> card-C2-41 | I21: =CONCATENATE("card-",$B21,"-",($C21-1)*9+I$1) -> card-C2-42 | J21: =CONCATENATE("card-",$B21,"-",($C21-1)*9+J$1) -> card-C2-43 | K21: =CONCATENATE("card-",$B21,"-",($C21-1)*9+K$1) -> card-C2-44 | L21: =CONCATENATE("card-",$B21,"-",($C21-1)*9+L$1) -> card-C2-45
B22: C2 | C22: =IF(EQ(B22,B21),C21+1,1) -> 6 | D22: =CONCATENATE("card-",$B22,"-",($C22-1)*9+D$1) -> card-C2-46 | E22: =CONCATENATE("card-",$B22,"-",($C22-1)*9+E$1) -> card-C2-47 | F22: =CONCATENATE("card-",$B22,"-",($C22-1)*9+F$1) -> card-C2-48 | G22: =CONCATENATE("card-",$B22,"-",($C22-1)*9+G$1) -> card-C2-49 | H22: =CONCATENATE("card-",$B22,"-",($C22-1)*9+H$1) -> card-C2-50 | I22: =CONCATENATE("card-",$B22,"-",($C22-1)*9+I$1) -> card-C2-51 | J22: =CONCATENATE("card-",$B22,"-",($C22-1)*9+J$1) -> card-C2-52 | K22: =CONCATENATE("card-",$B22,"-",($C22-1)*9+K$1) -> card-C2-53 | L22: =CONCATENATE("card-",$B22,"-",($C22-1)*9+L$1) -> card-C2-54
B23: C2 | C23: =IF(EQ(B23,B22),C22+1,1) -> 7 | D23: =CONCATENATE("card-",$B23,"-",($C23-1)*9+D$1) -> card-C2-55 | E23: =CONCATENATE("card-",$B23,"-",($C23-1)*9+E$1) -> card-C2-56 | F23: =CONCATENATE("card-",$B23,"-",($C23-1)*9+F$1) -> card-C2-57 | G23: =CONCATENATE("card-",$B23,"-",($C23-1)*9+G$1) -> card-C2-58 | H23: =CONCATENATE("card-",$B23,"-",($C23-1)*9+H$1) -> card-C2-59 | I23: =CONCATENATE("card-",$B23,"-",($C23-1)*9+I$1) -> card-C2-60 | J23: =CONCATENATE("card-",$B23,"-",($C23-1)*9+J$1) -> card-C2-61 | K23: =CONCATENATE("card-",$B23,"-",($C23-1)*9+K$1) -> card-C2-62 | L23: =CONCATENATE("card-",$B23,"-",($C23-1)*9+L$1) -> card-C2-63
B24: C2 | C24: =IF(EQ(B24,B23),C23+1,1) -> 8 | D24: =CONCATENATE("card-",$B24,"-",($C24-1)*9+D$1) -> card-C2-64 | E24: =CONCATENATE("card-",$B24,"-",($C24-1)*9+E$1) -> card-C2-65 | F24: =CONCATENATE("card-",$B24,"-",($C24-1)*9+F$1) -> card-C2-66 | G24: =CONCATENATE("card-",$B24,"-",($C24-1)*9+G$1) -> card-C2-67 | H24: =CONCATENATE("card-",$B24,"-",($C24-1)*9+H$1) -> card-C2-68 | I24: =CONCATENATE("card-",$B24,"-",($C24-1)*9+I$1) -> card-C2-69 | J24: =CONCATENATE("card-",$B24,"-",($C24-1)*9+J$1) -> card-C2-70 | K24: =CONCATENATE("card-",$B24,"-",($C24-1)*9+K$1) -> card-C2-71 | L24: =CONCATENATE("card-",$B24,"-",($C24-1)*9+L$1) -> card-C2-72
B25: C2 | C25: =IF(EQ(B25,B24),C24+1,1) -> 9 | D25: =CONCATENATE("card-",$B25,"-",($C25-1)*9+D$1) -> card-C2-73 | E25: =CONCATENATE("card-",$B25,"-",($C25-1)*9+E$1) -> card-C2-74 | F25: =CONCATENATE("card-",$B25,"-",($C25-1)*9+F$1) -> card-C2-75 | G25: =CONCATENATE("card-",$B25,"-",($C25-1)*9+G$1) -> card-C2-76 | H25: =CONCATENATE("card-",$B25,"-",($C25-1)*9+H$1) -> card-C2-77 | I25: =CONCATENATE("card-",$B25,"-",($C25-1)*9+I$1) -> card-C2-78 | J25: =CONCATENATE("card-",$B25,"-",($C25-1)*9+J$1) -> card-C2-79 | K25: =CONCATENATE("card-",$B25,"-",($C25-1)*9+K$1) -> card-C2-80 | L25: =CONCATENATE("card-",$B25,"-",($C25-1)*9+L$1) -> card-C2-81
B26: C2 | C26: =IF(EQ(B26,B25),C25+1,1) -> 10 | D26: =CONCATENATE("card-",$B26,"-",($C26-1)*9+D$1) -> card-C2-82 | E26: =CONCATENATE("card-",$B26,"-",($C26-1)*9+E$1) -> card-C2-83 | F26: =CONCATENATE("card-",$B26,"-",($C26-1)*9+F$1) -> card-C2-84 | G26: =CONCATENATE("card-",$B26,"-",($C26-1)*9+G$1) -> card-C2-85 | H26: =CONCATENATE("card-",$B26,"-",($C26-1)*9+H$1) -> card-C2-86 | I26: =CONCATENATE("card-",$B26,"-",($C26-1)*9+I$1) -> card-C2-87 | J26: =CONCATENATE("card-",$B26,"-",($C26-1)*9+J$1) -> card-C2-88 | K26: =CONCATENATE("card-",$B26,"-",($C26-1)*9+K$1) -> card-C2-89 | L26: =CONCATENATE("card-",$B26,"-",($C26-1)*9+L$1) -> card-C2-90
B27: C2 | C27: =IF(EQ(B27,B26),C26+1,1) -> 11 | D27: =CONCATENATE("card-",$B27,"-",($C27-1)*9+D$1) -> card-C2-91 | E27: =CONCATENATE("card-",$B27,"-",($C27-1)*9+E$1) -> card-C2-92 | F27: =CONCATENATE("card-",$B27,"-",($C27-1)*9+F$1) -> card-C2-93 | G27: =CONCATENATE("card-",$B27,"-",($C27-1)*9+G$1) -> card-C2-94 | H27: =CONCATENATE("card-",$B27,"-",($C27-1)*9+H$1) -> card-C2-95 | I27: =CONCATENATE("card-",$B27,"-",($C27-1)*9+I$1) -> card-C2-96 | J27: =CONCATENATE("card-",$B27,"-",($C27-1)*9+J$1) -> card-C2-97 | K27: Blank | L27: Blank
B28: C3 | C28: =IF(EQ(B28,B27),C27+1,1) -> 1 | D28: =CONCATENATE("card-",$B28,"-",($C28-1)*9+D$1) -> card-C3-1 | E28: =CONCATENATE("card-",$B28,"-",($C28-1)*9+E$1) -> card-C3-2 | F28: =CONCATENATE("card-",$B28,"-",($C28-1)*9+F$1) -> card-C3-3 | G28: =CONCATENATE("card-",$B28,"-",($C28-1)*9+G$1) -> card-C3-4 | H28: =CONCATENATE("card-",$B28,"-",($C28-1)*9+H$1) -> card-C3-5 | I28: =CONCATENATE("card-",$B28,"-",($C28-1)*9+I$1) -> card-C3-6 | J28: =CONCATENATE("card-",$B28,"-",($C28-1)*9+J$1) -> card-C3-7 | K28: =CONCATENATE("card-",$B28,"-",($C28-1)*9+K$1) -> card-C3-8 | L28: =CONCATENATE("card-",$B28,"-",($C28-1)*9+L$1) -> card-C3-9
B29: C3 | C29: =IF(EQ(B29,B28),C28+1,1) -> 2 | D29: =CONCATENATE("card-",$B29,"-",($C29-1)*9+D$1) -> card-C3-10 | E29: =CONCATENATE("card-",$B29,"-",($C29-1)*9+E$1) -> card-C3-11 | F29: =CONCATENATE("card-",$B29,"-",($C29-1)*9+F$1) -> card-C3-12 | G29: =CONCATENATE("card-",$B29,"-",($C29-1)*9+G$1) -> card-C3-13 | H29: =CONCATENATE("card-",$B29,"-",($C29-1)*9+H$1) -> card-C3-14 | I29: =CONCATENATE("card-",$B29,"-",($C29-1)*9+I$1) -> card-C3-15 | J29: =CONCATENATE("card-",$B29,"-",($C29-1)*9+J$1) -> card-C3-16 | K29: =CONCATENATE("card-",$B29,"-",($C29-1)*9+K$1) -> card-C3-17 | L29: =CONCATENATE("card-",$B29,"-",($C29-1)*9+L$1) -> card-C3-18
B30: C3 | C30: =IF(EQ(B30,B29),C29+1,1) -> 3 | D30: =CONCATENATE("card-",$B30,"-",($C30-1)*9+D$1) -> card-C3-19 | E30: =CONCATENATE("card-",$B30,"-",($C30-1)*9+E$1) -> card-C3-20 | F30: =CONCATENATE("card-",$B30,"-",($C30-1)*9+F$1) -> card-C3-21 | G30: =CONCATENATE("card-",$B30,"-",($C30-1)*9+G$1) -> card-C3-22 | H30: =CONCATENATE("card-",$B30,"-",($C30-1)*9+H$1) -> card-C3-23 | I30: =CONCATENATE("card-",$B30,"-",($C30-1)*9+I$1) -> card-C3-24 | J30: =CONCATENATE("card-",$B30,"-",($C30-1)*9+J$1) -> card-C3-25 | K30: =CONCATENATE("card-",$B30,"-",($C30-1)*9+K$1) -> card-C3-26 | L30: =CONCATENATE("card-",$B30,"-",($C30-1)*9+L$1) -> card-C3-27
B31: C3 | C31: =IF(EQ(B31,B30),C30+1,1) -> 4 | D31: =CONCATENATE("card-",$B31,"-",($C31-1)*9+D$1) -> card-C3-28 | E31: =CONCATENATE("card-",$B31,"-",($C31-1)*9+E$1) -> card-C3-29 | F31: =CONCATENATE("card-",$B31,"-",($C31-1)*9+F$1) -> card-C3-30 | G31: =CONCATENATE("card-",$B31,"-",($C31-1)*9+G$1) -> card-C3-31 | H31: =CONCATENATE("card-",$B31,"-",($C31-1)*9+H$1) -> card-C3-32 | I31: =CONCATENATE("card-",$B31,"-",($C31-1)*9+I$1) -> card-C3-33 | J31: =CONCATENATE("card-",$B31,"-",($C31-1)*9+J$1) -> card-C3-34 | K31: =CONCATENATE("card-",$B31,"-",($C31-1)*9+K$1) -> card-C3-35 | L31: =CONCATENATE("card-",$B31,"-",($C31-1)*9+L$1) -> card-C3-36
B32: C3 | C32: =IF(EQ(B32,B31),C31+1,1) -> 5 | D32: =CONCATENATE("card-",$B32,"-",($C32-1)*9+D$1) -> card-C3-37 | E32: =CONCATENATE("card-",$B32,"-",($C32-1)*9+E$1) -> card-C3-38 | F32: =CONCATENATE("card-",$B32,"-",($C32-1)*9+F$1) -> card-C3-39 | G32: =CONCATENATE("card-",$B32,"-",($C32-1)*9+G$1) -> card-C3-40 | H32: =CONCATENATE("card-",$B32,"-",($C32-1)*9+H$1) -> card-C3-41 | I32: =CONCATENATE("card-",$B32,"-",($C32-1)*9+I$1) -> card-C3-42 | J32: =CONCATENATE("card-",$B32,"-",($C32-1)*9+J$1) -> card-C3-43 | K32: =CONCATENATE("card-",$B32,"-",($C32-1)*9+K$1) -> card-C3-44 | L32: =CONCATENATE("card-",$B32,"-",($C32-1)*9+L$1) -> card-C3-45
B33: C3 | C33: =IF(EQ(B33,B32),C32+1,1) -> 6 | D33: =CONCATENATE("card-",$B33,"-",($C33-1)*9+D$1) -> card-C3-46 | E33: =CONCATENATE("card-",$B33,"-",($C33-1)*9+E$1) -> card-C3-47 | F33: =CONCATENATE("card-",$B33,"-",($C33-1)*9+F$1) -> card-C3-48 | G33: =CONCATENATE("card-",$B33,"-",($C33-1)*9+G$1) -> card-C3-49 | H33: =CONCATENATE("card-",$B33,"-",($C33-1)*9+H$1) -> card-C3-50 | I33: =CONCATENATE("card-",$B33,"-",($C33-1)*9+I$1) -> card-C3-51 | J33: =CONCATENATE("card-",$B33,"-",($C33-1)*9+J$1) -> card-C3-52 | K33: =CONCATENATE("card-",$B33,"-",($C33-1)*9+K$1) -> card-C3-53 | L33: =CONCATENATE("card-",$B33,"-",($C33-1)*9+L$1) -> card-C3-54
B34: C3 | C34: =IF(EQ(B34,B33),C33+1,1) -> 7 | D34: =CONCATENATE("card-",$B34,"-",($C34-1)*9+D$1) -> card-C3-55 | E34: =CONCATENATE("card-",$B34,"-",($C34-1)*9+E$1) -> card-C3-56 | F34: =CONCATENATE("card-",$B34,"-",($C34-1)*9+F$1) -> card-C3-57 | G34: Blank | H34: Blank | I34: Blank | J34: Blank | K34: Blank | L34: Blank

Sheet line
